<mujoco model="reacher">
	<compiler inertiafromgeom="true" angle="radian" coordinate="local" texturedir="textures" meshdir="stl_files"/>
	<option timestep="0.01" gravity="0 0 -9.81" integrator="RK4"/>
	<default >
		<joint limited="true" armature="1" damping="1"/>
		<geom friction="1.2 1.0 1.0" contype="0" rgba="0.7 0.7 0 1"/>
	</default>
	<worldbody >
		<light pos="0 0 1.3" cutoff="100" diffuse="1 1 1" dir="-0 0 -1.3" exponent="1" specular=".1 .1 .1" directional="true"/>
		<geom pos="0 0 0" contype="1" name="table" size="1 1 0.1" conaffinity="1" friction="0.1 0 0.0" type="plane" material="table_material"/>
		<body pos="0 0 0.3" name="gripper">
			<geom contype="0" name="link0" rgba="0.9 0.3 0.3 1" size="0.01" conaffinity="0" type="capsule" fromto="-0.012 0 0 0.012 0 0"/>
			<joint axis="1 0 0" type="slide" pos="0 0 0" name="joint_x" limited="false"/>
			<joint axis="0 1 0" type="slide" pos="0 0 0" name="joint_y" limited="false"/>
			<joint axis="0 0 1" type="slide" pos="0 0 0" name="joint_z" limited="false"/>
			<joint pos="0 0 0" name="gripper_hinge_z" armature="0" damping="0.0001" axis="0 0 1" type="hinge" limited="false" stiffness="0"/>
			<body pos="-0.012 0 -0.01" name="fingertip1">
				<joint pos="0 0 0" range="0 0.024" name="joint_tip" axis="1 0 0" type="slide" limited="true"/>
				<geom contype="1" name="ft1" rgba="0.9 0.3 0.3 1" size="0.0025 0.0025 0.02" conaffinity="1" type="box" friction="2 0.010 0.0002"/>
			</body>
			<body pos="0.012 0 -0.01" name="fingertip2">
				<geom contype="1" name="ft2" rgba="0.9 0.3 0.3 1" size="0.0025 0.0025 0.02" conaffinity="1" type="box" friction="2 0.010 0.0002"/>
			</body>
		</body>
		<body pos="0 0 0" name="target">
			<geom user="1" pos="0 0 0" contype="1" name="target" rgba="0.2 0.3 0.5 1" size="0.02 0.005" conaffinity="1" type="cylinder" friction="2 0.010 0.0002"/>
			<joint pos="0 0 0" name="target_x" armature="0" damping="0" axis="1 0 0" type="slide" limited="false" stiffness="0"/>
			<joint pos="0 0 0" name="target_y" armature="0" damping="0" axis="0 1 0" type="slide" limited="false" stiffness="0"/>
			<joint pos="0 0 0" name="target_z" armature="0" damping="0" axis="0 0 1" type="slide" limited="false" stiffness="0"/>
			<joint pos="0 0 0" name="target_hinge_z" armature="0" damping="0" axis="0 0 1" type="hinge" limited="false" stiffness="0"/>
			<body pos="0 0 0" name="handle">
				<geom user="1" pos="0.025 0 0" contype="1" name="handle" rgba="0.2 0.3 0.5 1" size="0.02 0.0025 0.0025" conaffinity="1" type="box" friction="2 0.010 0.0002"/>
			</body>
		</body>
	</worldbody>
	<actuator >
		<position joint="joint_x" kp="2" ctrllimited="false"/>
		<position joint="joint_y" kp="2" ctrllimited="false"/>
		<position joint="joint_z" kp="3" ctrllimited="false"/>
		<velocity joint="joint_z" kv="0.5" ctrllimited="false"/>
		<motor joint="joint_tip" ctrlrange="-5.0 5.0" ctrllimited="true"/>
	</actuator>
	<asset >
        <texture type="2d" file="/home/dineshj/Documents/Codes/lowcostgrasp/simulator/assets/wood-texture/pic_011.png" name="table_texture"/>
		<material texrepeat="10 10" texture="table_texture" shininess="0.1" specular="0.4" name="table_material"/>
	</asset>
</mujoco>
