<mujoco model="grasper">
	<compiler inertiafromgeom="true" angle="radian" coordinate="local" meshdir="meshes" texturedir="textures"/>
	<option timestep="0.01" gravity="0 0 -9.81" tolerance="1e-12" impratio="10" noslip_iterations="100" cone="elliptic"/>
	<default >
		<joint armature="1" damping="1" limited="true"/>
		<geom friction="5 0.1 0.1" condim="4" contype="1" conaffinity="1" solimp="0.999 0.999 0.01" solref="0.01 1" rgba="1 1 1 1"/>
	</default>
	<asset >
		<texture name="target0_texture" file="object_textures/pic_001.png"/>
		<material shininess="0.3" specular="1" name="target0_material" rgba="1 1 1 1" texture="target0_texture"/>
		<texture name="target1_texture" file="object_textures/pic_001.png"/>
		<material shininess="0.3" specular="1" name="target1_material" rgba="1 1 1 1" texture="target1_texture"/>
		<texture name="target2_texture" file="object_textures/pic_001.png"/>
		<material shininess="0.3" specular="1" name="target2_material" rgba="1 1 1 1" texture="target2_texture"/>
		<texture name="target3_texture" file="object_textures/pic_001.png"/>
		<material shininess="0.3" specular="1" name="target3_material" rgba="1 1 1 1" texture="target3_texture"/>
		<texture name="table_texture" file="wood_table.png" type="2d"/>
		<material shininess="0.1" specular="0.4" name="table_material" texture="table_texture" texrepeat="10 10"/>
	</asset>
	<worldbody >
		<light directional="true" castshadow="false" cutoff="100" diffuse="1 1 1" specular=".1 .1 .1" exponent="1" pos="0 0 1.3" dir="-0 0 -1.3"/>
		<geom name="table" condim="4" material="table_material" type="plane" rgba="1 1 1 1" pos="0 0 0" size="1 1 0.1" conaffinity="1" contype="1" friction="1 1 1"/>
		<body name="gripper" pos="0.0 0.0 0.2">
			<geom name="link0" condim="4" type="capsule" fromto="-0.012 0 0 0.012 0 0" rgba="0.9 0.3 0.3 1" size="0.01" conaffinity="1" contype="1" density="2000"/>
			<joint name="joint_x" type="slide" limited="false" pos="0 0 -1.5" axis="1 0 0"/>
			<joint name="joint_y" type="slide" limited="false" pos="0 0 -1.5" axis="0 1 0"/>
			<joint name="joint_z" type="slide" limited="false" pos="0 0 -1.5" axis="0 0 1"/>
			<joint name="gripper_hinge_z" type="hinge" pos="0 0 -1.5" axis="0 0 1" armature="0" damping="0.0001" stiffness="0" limited="false"/>
			<body name="fingertip1" pos="-0.012 0 -0.01">
				<joint axis="1 0 0" name="joint_tip" pos="0 0 0" limited="true" range="0 0.024" type="slide"/>
				<geom condim="4" size="0.0025 0.0025 0.02" name="ft1" rgba="0.9 0.3 0.3 1" type="box" conaffinity="1" contype="1" friction="2 0.010 0.0002" density="2000"/>
			</body>
			<body name="fingertip2" pos="0.012 0 -0.01">
				<geom condim="4" size="0.0025 0.0025 0.02" name="ft2" rgba="0.9 0.3 0.3 1" type="box" conaffinity="1" contype="1" friction="2 0.010 0.0002" density="2000"/>
			</body>
		</body>
		<body name="target0" pos="0.0 0.0 0.0">
			<geom condim="4" size="0.005 0.025 0.01" name="targetbox0" material="target0_material" rgba="0.1 0.3 0.3 1" type="box" conaffinity="1" contype="1" friction="2 0.010 0.0002" density="2000"/>
			<joint name="target0_x" type="slide" pos="0 0 0" axis="1 0 0" armature="0" damping="0" stiffness="0" limited="false"/>
			<joint name="target0_y" type="slide" pos="0 0 0" axis="0 1 0" armature="0" damping="0" stiffness="0" limited="false"/>
			<joint name="target0_z" type="slide" pos="0 0 0" axis="0 0 1" armature="0" damping="0" stiffness="0" limited="false"/>
			<joint name="target0_hinge_z" type="hinge" pos="0 0 0" axis="0 0 1" armature="0" damping="0" stiffness="0" limited="false"/>
		</body>
		<body name="target1" pos="0.0 0.0 0.0">
			<geom condim="4" size="0.01 0.01 0.005" name="targetsphere1" material="target1_material" rgba="0.1 0.3 0.3 1" type="sphere" conaffinity="1" contype="1" friction="2 0.010 0.0002" density="2000"/>
			<joint name="target1_x" type="slide" pos="0 0 0" axis="1 0 0" armature="0" damping="0" stiffness="0" limited="false"/>
			<joint name="target1_y" type="slide" pos="0 0 0" axis="0 1 0" armature="0" damping="0" stiffness="0" limited="false"/>
			<joint name="target1_z" type="slide" pos="0 0 0" axis="0 0 1" armature="0" damping="0" stiffness="0" limited="false"/>
			<joint name="target1_hinge_z" type="hinge" pos="0 0 0" axis="0 0 1" armature="0" damping="0" stiffness="0" limited="false"/>
		</body>
		<body name="target2" pos="0.0 0.0 0.0">
			<geom condim="4" size="0.01 0.01 0.005" name="targetcylinder2" material="target2_material" rgba="0.1 0.3 0.3 1" type="cylinder" conaffinity="1" contype="1" friction="2 0.010 0.0002" density="2000"/>
			<joint name="target2_x" type="slide" pos="0 0 0" axis="1 0 0" armature="0" damping="0" stiffness="0" limited="false"/>
			<joint name="target2_y" type="slide" pos="0 0 0" axis="0 1 0" armature="0" damping="0" stiffness="0" limited="false"/>
			<joint name="target2_z" type="slide" pos="0 0 0" axis="0 0 1" armature="0" damping="0" stiffness="0" limited="false"/>
			<joint name="target2_hinge_z" type="hinge" pos="0 0 0" axis="0 0 1" armature="0" damping="0" stiffness="0" limited="false"/>
		</body>
		<body name="target3" pos="0.0 0.0 0.0">
			<geom condim="4" size="0.005 0.02 0.01" name="targetellipsoid3" material="target3_material" rgba="0.1 0.3 0.3 1" type="ellipsoid" conaffinity="1" contype="1" friction="2 0.010 0.0002" density="2000"/>
			<joint name="target3_x" type="slide" pos="0 0 0" axis="1 0 0" armature="0" damping="0" stiffness="0" limited="false"/>
			<joint name="target3_y" type="slide" pos="0 0 0" axis="0 1 0" armature="0" damping="0" stiffness="0" limited="false"/>
			<joint name="target3_z" type="slide" pos="0 0 0" axis="0 0 1" armature="0" damping="0" stiffness="0" limited="false"/>
			<joint name="target3_hinge_z" type="hinge" pos="0 0 0" axis="0 0 1" armature="0" damping="0" stiffness="0" limited="false"/>
		</body>
	</worldbody>
	<actuator >
		<position joint="joint_x" ctrllimited="false" kp="2"/>
		<position joint="joint_y" ctrllimited="false" kp="2"/>
		<position joint="joint_z" ctrllimited="false" kp="16"/>
		<velocity joint="joint_z" ctrllimited="false" kv="8"/>
		<motor joint="joint_tip" ctrlrange="-5.0 5.0" ctrllimited="true"/>
	</actuator>
</mujoco>
